Traceback (most recent call last):
  File "/home/simon/venvs/py3/qutip-scipy-2022/lib/python3.9/site-packages/jupyter_cache/executors/utils.py", line 51, in single_nb_execution
    executenb(
  File "/home/simon/venvs/py3/qutip-scipy-2022/lib/python3.9/site-packages/nbclient/client.py", line 1204, in execute
    return NotebookClient(nb=nb, resources=resources, km=km, **kwargs).execute()
  File "/home/simon/venvs/py3/qutip-scipy-2022/lib/python3.9/site-packages/nbclient/util.py", line 84, in wrapped
    return just_run(coro(*args, **kwargs))
  File "/home/simon/venvs/py3/qutip-scipy-2022/lib/python3.9/site-packages/nbclient/util.py", line 62, in just_run
    return loop.run_until_complete(coro)
  File "/usr/lib/python3.9/asyncio/base_events.py", line 647, in run_until_complete
    return future.result()
  File "/home/simon/venvs/py3/qutip-scipy-2022/lib/python3.9/site-packages/nbclient/client.py", line 663, in async_execute
    await self.async_execute_cell(
  File "/home/simon/venvs/py3/qutip-scipy-2022/lib/python3.9/site-packages/nbclient/client.py", line 965, in async_execute_cell
    await self._check_raise_for_error(cell, cell_index, exec_reply)
  File "/home/simon/venvs/py3/qutip-scipy-2022/lib/python3.9/site-packages/nbclient/client.py", line 862, in _check_raise_for_error
    raise CellExecutionError.from_cell_and_msg(cell, exec_reply_content)
nbclient.exceptions.CellExecutionError: An error occurred while executing the following cell:
------------------
atoms = [(1, 0), (0, 1)]
circuit = NeutralAtomCircuit(atoms)

# Example circuit 1: Pretty sequence of rotations the form a closed loop (qubit 0)
#circuit.rx(0, np.pi / 4)
#circuit.rz(0, np.pi / 4)
#circuit.ry(0, np.pi / 4)

# Example circuit 2: Pretty sequence of rotations the form a closed loop (qubit 1)
#circuit.rx(1, np.pi / 4)
#circuit.rz(1, np.pi / 4)
#circuit.ry(1, np.pi / 4)

# Example circuit 3:
# Combine the two pervious circuits into one

# Example circuit 4: Apply a CNOT
# CNOT = (I âŠ— H)CZ(I âŠ— H)
# H = X Ry(pi/2)
circuit.rx(1, np.pi / 2)
circuit.ry(1, np.pi / 4)
circuit.cz(0, 1)
circuit.rx(1, np.pi / 2)
circuit.ry(1, np.pi / 4)

psi = circuit.state("11")
result = circuit.run(psi, step_rate=20)

# print(circuit.t, result.times)
state_idx = [0, -1]
if state_idx:
    computational_basis_blochs([result.states[i] for i in state_idx], "rb")
computational_basis_blochs(result.states, "rb")

print(qutip.expect(circuit.rr[0], result.states[0::10]))
print(qutip.expect(circuit.rr[1], result.states[0::10]))
len(result.states)
------------------

[0;31m---------------------------------------------------------------------------[0m
[0;31mNameError[0m                                 Traceback (most recent call last)
Input [0;32mIn [5][0m, in [0;36m<cell line: 31>[0;34m()[0m
[1;32m     30[0m state_idx [38;5;241m=[39m [[38;5;241m0[39m, [38;5;241m-[39m[38;5;241m1[39m]
[1;32m     31[0m [38;5;28;01mif[39;00m state_idx:
[0;32m---> 32[0m     [43mcomputational_basis_blochs[49m([result[38;5;241m.[39mstates[i] [38;5;28;01mfor[39;00m i [38;5;129;01min[39;00m state_idx], [38;5;124m"[39m[38;5;124mrb[39m[38;5;124m"[39m)
[1;32m     33[0m computational_basis_blochs(result[38;5;241m.[39mstates, [38;5;124m"[39m[38;5;124mrb[39m[38;5;124m"[39m)
[1;32m     35[0m [38;5;28mprint[39m(qutip[38;5;241m.[39mexpect(circuit[38;5;241m.[39mrr[[38;5;241m0[39m], result[38;5;241m.[39mstates[[38;5;241m0[39m::[38;5;241m10[39m]))

[0;31mNameError[0m: name 'computational_basis_blochs' is not defined
NameError: name 'computational_basis_blochs' is not defined

